<?xml version="1.0" ?>
<robot name="am" xmlns:xacro="http://ros.org/wiki/xacro">

  <!-- ****************** MATHS CONSTANTS *******************************  -->
  <!-- Define generic, usefule maths constants -->
  <xacro:property name="pi2" value="1.57079632679"/>

  <!-- ****************** ROBOT CONSTANTS *******************************  -->
  <!-- Define the size of the robot's main chassis in meters -->
  <xacro:property name="width" value="0.03"/>
  <xacro:property name="length" value="0.02"/>
  <xacro:property name="joint_offset" value="0.04"/>

  <material name="black">
    <color rgba="0.0 0.0 0.0 1.0"/>
  </material>

  <material name="trans_grey">
    <color rgba="0.4 0.4 0.4 0.35"/>
  </material>
  
  <!-- ****************** ROBOT FLYING BASE ************************************  -->
  <link name="base_link">
    <visual>
      <origin xyz="-0.725 -0.35 -0.615" rpy="1.57 0 1.57"/>
      <geometry>
        <mesh filename="package://rviz_vis/meshes/TactileMappingDroneBase.dae"
              scale="1 1 1"/>
      </geometry>
    </visual>
    <collision>
      <origin xyz="0 0 0" rpy="0 0 0"/>
      <geometry>
        <box size="0.5 0.5 0.1"/>
      </geometry>
    </collision>
  </link>

  <link name="link1">
    <visual>
      <origin xyz="-0.01 -0.005 0.0525" rpy="0 -1.57 0"/>
      <geometry>
        <mesh filename="package://rviz_vis/meshes/Link1.dae"
              scale="1 1 1"/>
      </geometry>
    </visual>
    <collision>
      <origin xyz="-0.0175 0 0" rpy="0 -1.57 0"/>
      <geometry>
        <cylinder radius="0.01" length="0.12"/>
      </geometry>
    </collision>
  </link>

  <link name="link2">
    <visual>
      <origin xyz="-0.006 0.0025 -0.0075" rpy="1.57 0 -1.57"/>
      <geometry>
        <mesh filename="package://rviz_vis/meshes/Link2Assembly.dae"
              scale="0.001 0.001 0.001"/>
      </geometry>
    </visual>
    <collision>
      <origin xyz="0.0 0.0 0.0075" rpy="0.0 0 0.0"/>
      <geometry>
        <box size="0.07 0.05 0.01"/>
      </geometry>
    </collision>
  </link>

  <link name="ee">
    <collision>
      <origin xyz="0.0 0.0 -0.01" rpy="0.0 0 0.0"/>
      <geometry>
        <sphere radius="0.01"/>
      </geometry>
    </collision>
  </link>


  <!-- ################ Joints ##################### -->
  <joint name="linear_joint" type="prismatic">
    <parent link="base_link"/>
    <child link="link1"/>
    <origin xyz="0.3 0 -0.03" rpy="1.57 0 0"/>
    <limit lower="-0.05" upper="0.00" velocity="1000" effort="1000"/>
  </joint>

  <joint name="revolute_joint" type="revolute">
    <parent link="link1"/>
    <child link="link2"/>
    <origin xyz="0.042 0 0" rpy="1.57 0 1.57"/>
    <limit lower="-0.785398163" upper="0.785398163" velocity="1000" effort="1000"/>
  </joint>

  <joint name="ee_connector" type="fixed">
    <parent link="link2"/>
    <child link="ee"/>
    <origin xyz="0.0 0.0 0.028" rpy="0 0 0"/>
  </joint>    

</robot>
